Importing Initial Conditions...
Importing Knot File:  /home/brandon/casadi/ccp_paths/4.5m37.70961741503379.csv
Path Duration:  766.3766611454236
Enforcing Convex Hull Obstacle...
Solving OCP...

******************************************************************************
This program contains Ipopt, a library for large-scale nonlinear optimization.
 Ipopt is released as open source code under the Eclipse Public License (EPL).
         For more information visit https://github.com/coin-or/Ipopt
******************************************************************************

Saving Solution:  /home/brandon/casadi/ocp_paths/all_ccp/4.5m
Importing Initial Conditions...
Importing Knot File:  /home/brandon/casadi/ccp_paths/1.5m39.54650040858009.csv
Path Duration:  618.4228724093282
Enforcing Convex Hull Obstacle...
Solving OCP...
multiprocessing.pool.RemoteTraceback: 
"""
Traceback (most recent call last):
  File "/home/brandon/anaconda3/envs/casadi/lib/python3.12/multiprocessing/pool.py", line 125, in worker
    result = (True, func(*args, **kwds))
                    ^^^^^^^^^^^^^^^^^^^
  File "/home/brandon/casadi/casadi_opti_station.py", line 19, in ocp_parallel
    ocp_station_knot(save_folder=save_dir,
  File "/home/brandon/casadi/casadi_opti_station.py", line 149, in ocp_station_knot
    sol = opti.solve()
          ^^^^^^^^^^^^
  File "/home/brandon/anaconda3/envs/casadi/lib/python3.12/site-packages/casadi/casadi.py", line 47860, in solve
    return _casadi.Opti_solve(self, *args)
           ^^^^^^^^^^^^^^^^^^^^^^^^^^^^^^^
RuntimeError: Error in Opti::solve [OptiNode] at .../casadi/core/optistack.cpp:157:
.../casadi/core/optistack_internal.cpp:996: Assertion "return_success(accept_limit)" failed:
Solver failed. You may use opti.debug.value to investigate the latest values of variables. return_status is 'Infeasible_Problem_Detected'
"""

The above exception was the direct cause of the following exception:

Traceback (most recent call last):
  File "/home/brandon/casadi/final_path_solve.py", line 62, in <module>
    generate_soln_parallel(thrust_limit=1.0,
  File "/home/brandon/casadi/final_path_solve.py", line 58, in generate_soln_parallel
    r = list(p.imap(ocp_parallel, arg_list))
        ^^^^^^^^^^^^^^^^^^^^^^^^^^^^^^^^^^^^
  File "/home/brandon/anaconda3/envs/casadi/lib/python3.12/multiprocessing/pool.py", line 873, in next
    raise value
RuntimeError: Error in Opti::solve [OptiNode] at .../casadi/core/optistack.cpp:157:
.../casadi/core/optistack_internal.cpp:996: Assertion "return_success(accept_limit)" failed:
Solver failed. You may use opti.debug.value to investigate the latest values of variables. return_status is 'Infeasible_Problem_Detected'
